Workbook

Sheet Instructions
A1: Instructions
A2: Step 1 | B2: Run DSR like normal
A3: Step 2 | B3: Fill out the "Actual Start" and "Actual End" dates in "Target Schedule" section
A4: Step 3 | B4: Go to the "Daily Target" sheet. This sheet will automatically create a daily target based on the planned test cases
B5: If you wish to change the daily targets, feel free to replace column B and C with your own numbers
A6: Step 4 | B6: Go to the "AssignPeopleToDepartments" sheet and assign any ALM ids to their departments | M6: need to be fixed
B7: This sheet pulls all the people who have been assigned defects. As defects get created and assigned to new people, you will have to go back to this sheet and assign them
B8: If cell "G161" has an error message in it, that means there are people in the "AssignPeopleToDepartments" sheet that are not yet assigned a department
A9: Step 5 | B9: If the summary in cell "A11" has an error message, make sure that the "Actual Start", "Actual End" dates are filled in and that the "Daily Target" sheet is filled in
B10: Once those cells are filled in, you can rerun the DSR to create the summary
B11: *Note, the first time you run the DSR on a project/a new cycle starts, the summary is likely to be wrong or error. Ensure the abovementioned fields are filled in and rerun
A12: Done | B12: There is a button in the "Login" sheet that you can press to copy the DSR to clipboard

Sheet Login
J3: Domain Name | K3: MLIDT
J4: ALM Project Name | K4: Lending_F25
J5: Release | K5: PBPTINTK-3366 - OSFI MVP 8.2 - 1E
J6: Release Index

Sheet Releases
A1: REL_ID | B1: REL_NAME | C1: PROJECT | D1: REL_END_DATE
A2: 1165 | B2: 16393 Misc DM fixes | C2: 16393 Misc DM fixes | D2: 45933
A3: 1130 | B3: 22272- Total Asset | C3: 22272- Total Asset | D3: 45870
A4: 1062 | B4: 3624-30-Yr-AM-DM-CLASS-mMTG-FEB 2025-Release | C4: 3624-30-Yr-AM-DM-CLASS-mMTG-FEB 2025-Release | D4: 45688
A5: 1129 | B5: 3624-30-YR-Amortization | C5: 3624-30-Yr-Amortization-Jul2025-Release | D5: 45870
A6: 1061 | B6: 3624-30-Yr-Amortization-Jan 2025-Release | C6: 3624-30-Yr-Amortization-Jan 2025-Release | D6: 45672
A7: 1037 | B7: 3624-30-Yr-Amortization-Nov-Release | C7: 3624-30 Yr amortization-Nov release | D7: 45625
A8: 1083 | B8: April 6 Release Regression Testing - Lending & ECTT Services 25.3 (Apr 6, 2025) | C8: April 6 Release Regression Testing - Lending & ECTT Services 25.3 (Apr 6, 2025) | D8: 45737
A9: 1103 | B9: April Release Lending Bundled PAT | C9: April Release | D9: 45748
A10: 1041 | B10: Feb 2 release regression testing - Lending & ECTT Services 25.2 | C10: Feb 2 release regression testing - Lending & ECTT Services 25.2 | D10: 45674
A11: 1074 | B11: February Release PAT | C11: PAT | D11: 45681
A12: 1065 | B12: INC16699108 – C0038 logs folder create in production | C12: INC16699108 – C0038 logs folder create in production | D12: 45661
A13: 1134 | B13: July 20 Release Regression Testing - Lending & ECTT Services 25.4 (Jul 20, 2025) | C13: July 20 Release Regression Testing - Lending & ECTT Services 25.4 (Jul 20, 2025) | D13: 45870
... A54: 1066 | B54: PBPT2616 Renewal Due Diligence - MVP1.1 Mass | C54: PBPT2616 Renewal Due Diligence - MVP1.1 Mass | D54: 45765
A55: 1097 | B55: PBPT2616 Renewal Due Diligence - MVP2 | C55: 2616 | D55: 45849
A56: 1089 | B56: PBPT2616 Renewal Due Diligence – MVP1 Mass Launch | C56: PBPT2616 Renewal Due Diligence – MVP1 Mass Launch | D56: 45765
A57: 1120 | B57: PBPT2616 Renewal Due Diligence – MVP2 | C57: PBPT2616 Renewal Due Diligence – MVP2 | D57: 45947
A58: 1155 | B58: PBPT2800 CA Foundation - IDP MVP2 Business UAT_August Release | C58: PBPT2800 CA Foundation - IDP MVP2 | D58: 45875
A59: 1007 | B59: PBPT3325 HPP Amendment Pkg in Quebec | C59: PBPT3325 HPP Amendment Pkg in Quebec | D59: 45625
A60: 1004 | B60: PBPT3384-AMS2024(CIBC_NON_CIBC) | C60: AMS2024 | D60: 45590
A61: 1015 | B61: PBPTINKT-3657 - Update CIBC Signature on HPP Loan Terms | C61: PBPTINKT-3657 - Update CIBC Signature on HPP Loan Terms | D61: 45625
A62: 1093 | B62: PBPTINTK – 3135 PLC Payout Balance | C62: PBPTINTK – 3135 PLC Payout Balance | D62: 45765
A63: 1082 | B63: PBPTINTK – 3746 – PLC Letter 70 Automation | C63: PBPTINTK – 3746 – PLC Letter 70 Automation | D63: 45765
A64: 1060 | B64: PBPTINTK 2444 CR 17 | C64: PBPTINTK 2444 CR17 | D64: 45649
A65: 1068 | B65: PBPTINTK 2921 - LCMS Routing | C65: PBPTINTK 2921 - LCMS Routing | D65: 45774
A66: 1040 | B66: PBPTINTK 3081 - Hopper 1 - Insurer Enhancements | C66: PBPTINTK 3081 - Hopper 1 - Insurer Enhancements | D66: 45753
A67: 1113 | B67: PBPTINTK 3081 - Hopper 1 - Warranty Fixes | C67: PBPTINTK 3081 - Hopper 1 - Insurer Enhancements & Prior Charges | D67: 45763
... A169: 1144 | B169: Sept 21 Release Regression Testing - Lending & ECTT Services 25.5 (Sep 21, 2025) | C169: Sept 21 Release Regression Testing - Lending & ECTT Services 25.5 (Sep 21, 2025) | D169: 45921

Sheet Recent Credentials
A1: URL | B1: https://alm.cibc.com:8443/qcbin
A2: Domain | B2: MLIDT
A3: Project | B3: Lending_F25
A4: UserName

Sheet Target Schedule
A1: Cycle / Sprint | B1: Planned Start | C1: Actual Start | D1: Planned End | E1: Actual End
A2: SIT Cycle 1 | B2: 45754 | D2: 45779
A3: SIT Cycle 2 | B3: 45782 | D3: 45812
A4: UAT Cycle 1 | B4: 45813 | D4: 45833
A5: UAT Cycle 2 | B5: 45834 | D5: 45847

Sheet Test Coverage
A1: Cycle | B1: Daily Throughput | C1: # Manual TCs | D1: # Automated TCs* | E1: % Total TCs
A2: SIT Cycle 1 | B2: Total Executed | C2: 0 | D2: 0
A3: SIT Cycle 1 | B3: Passed | C3: 0 | D3: 0
A4: SIT Cycle 1 | B4: Failed | C4: 0 | D4: 0
A5: SIT Cycle 1 | B5: Not Completed | C5: 0 | D5: 0
A6: SIT Cycle 1 | B6: Blocked | C6: 0 | D6: 0
A7: SIT Cycle 1 | B7: No Run | C7: 0 | D7: 0
A8: SIT Cycle 1 | B8: N/A (Descoped) | C8: 0 | D8: 0
A9: SIT Cycle 2 | B9: Total Executed | C9: 0 | D9: 0
A10: SIT Cycle 2 | B10: Passed | C10: 0 | D10: 0
A11: SIT Cycle 2 | B11: Failed | C11: 0 | D11: 0
A12: SIT Cycle 2 | B12: Not Completed | C12: 0 | D12: 0
A13: SIT Cycle 2 | B13: Blocked | C13: 0 | D13: 0
... A29: UAT Cycle 2 | B29: N/A (Descoped) | C29: 0 | D29: 0

Sheet Cumulative Test Coverage
A1: Cycle | B1: Cumulative Totals by Phase | C1: # Manual TCs | D1: # Automated Regression TCs | E1: % Automation Usage | F1: % Total TCs
A2: SIT Cycle 1 | B2: Total Planned | C2: 126 | D2: 290
A3: SIT Cycle 1 | B3: Total Executed | C3: 61 | D3: 149
A4: SIT Cycle 1 | B4: Passed | C4: 60 | D4: 143
A5: SIT Cycle 1 | B5: Failed | C5: 1 | D5: 6
A6: SIT Cycle 1 | B6: Not Completed | C6: 0 | D6: 0
A7: SIT Cycle 1 | B7: Blocked | C7: 0 | D7: 0
A8: SIT Cycle 1 | B8: No Run | C8: 0 | D8: 0
A9: SIT Cycle 1 | B9: N/A (Descoped) | C9: 0 | D9: 0
A10: SIT Cycle 2 | B10: Total Planned | C10: 142 | D10: 378
A11: SIT Cycle 2 | B11: Total Executed | C11: 142 | D11: 378
A12: SIT Cycle 2 | B12: Passed | C12: 141 | D12: 378
A13: SIT Cycle 2 | B13: Failed | C13: 1 | D13: 0
... A33: UAT Cycle 2 | B33: N/A (Descoped) | C33: 0 | D33: 0

Sheet Daily Variance
A1: Variances | B1: #
A2: Created | B2: 0
A3: Closed | B3: 0
A4: Opened & Closed on Same Day | B4: 0

Sheet CumVar by Severity & Status
A1: RCYC_NAME | B1: SEV_NUM | C1: SEV_NAME | D1: REL_ID | E1: REL_NAME | F1: PROJECT | G1: REL_END_DATE | H1: New | I1: Opened | J1: Fixed | K1: Awaiting | L1: Monitor | M1: Reopen | N1: Deferred | O1: Rejected | P1: Closed | Q1: Total
A2: SIT Cycle 1 | B2: 1 | C2: 1 - Showstopper | D2: 1099 | E2: PBPTINTK-3366 - OSFI MVP 8.2 - 1E | F2: PBPTINTK-3366 - OSFI MVP 8.2 - 1E | G2: 45858 | H2: 0 | I2: 0 | J2: 0 | K2: 0 | L2: 0 | M2: 0 | N2: 0 | O2: 0 | P2: 7 | Q2: 7
A3: SIT Cycle 1 | B3: 2 | C3: 2 - Critical | D3: 1099 | E3: PBPTINTK-3366 - OSFI MVP 8.2 - 1E | F3: PBPTINTK-3366 - OSFI MVP 8.2 - 1E | G3: 45858 | H3: 0 | I3: 0 | J3: 0 | K3: 0 | L3: 0 | M3: 0 | N3: 0 | O3: 0 | P3: 34 | Q3: 34
A4: SIT Cycle 1 | B4: 3 | C4: 3 - Non-critical | D4: 1099 | E4: PBPTINTK-3366 - OSFI MVP 8.2 - 1E | F4: PBPTINTK-3366 - OSFI MVP 8.2 - 1E | G4: 45858 | H4: 0 | I4: 0 | J4: 0 | K4: 0 | L4: 0 | M4: 0 | N4: 0 | O4: 0 | P4: 19 | Q4: 19
A5: SIT Cycle 1 | B5: 4 | C5: 4 - Live with | D5: 1099 | E5: PBPTINTK-3366 - OSFI MVP 8.2 - 1E | F5: PBPTINTK-3366 - OSFI MVP 8.2 - 1E | G5: 45858 | H5: 0 | I5: 0 | J5: 0 | K5: 0 | L5: 0 | M5: 0 | N5: 0 | O5: 0 | P5: 0 | Q5: 0
A6: SIT Cycle 2 | B6: 1 | C6: 1 - Showstopper | D6: 1099 | E6: PBPTINTK-3366 - OSFI MVP 8.2 - 1E | F6: PBPTINTK-3366 - OSFI MVP 8.2 - 1E | G6: 45858 | H6: 0 | I6: 0 | J6: 0 | K6: 0 | L6: 0 | M6: 0 | N6: 0 | O6: 0 | P6: 4 | Q6: 4
A7: SIT Cycle 2 | B7: 2 | C7: 2 - Critical | D7: 1099 | E7: PBPTINTK-3366 - OSFI MVP 8.2 - 1E | F7: PBPTINTK-3366 - OSFI MVP 8.2 - 1E | G7: 45858 | H7: 0 | I7: 0 | J7: 0 | K7: 0 | L7: 0 | M7: 0 | N7: 1 | O7: 0 | P7: 13 | Q7: 14
A8: SIT Cycle 2 | B8: 3 | C8: 3 - Non-critical | D8: 1099 | E8: PBPTINTK-3366 - OSFI MVP 8.2 - 1E | F8: PBPTINTK-3366 - OSFI MVP 8.2 - 1E | G8: 45858 | H8: 0 | I8: 0 | J8: 0 | K8: 0 | L8: 0 | M8: 0 | N8: 0 | O8: 0 | P8: 22 | Q8: 22
A9: SIT Cycle 2 | B9: 4 | C9: 4 - Live with | D9: 1099 | E9: PBPTINTK-3366 - OSFI MVP 8.2 - 1E | F9: PBPTINTK-3366 - OSFI MVP 8.2 - 1E | G9: 45858 | H9: 0 | I9: 0 | J9: 0 | K9: 0 | L9: 0 | M9: 0 | N9: 0 | O9: 0 | P9: 0 | Q9: 0
A10: UAT Cycle 1 | B10: 1 | C10: 1 - Showstopper | D10: 1099 | E10: PBPTINTK-3366 - OSFI MVP 8.2 - 1E | F10: PBPTINTK-3366 - OSFI MVP 8.2 - 1E | G10: 45858 | H10: 0 | I10: 0 | J10: 0 | K10: 0 | L10: 0 | M10: 0 | N10: 0 | O10: 0 | P10: 1 | Q10: 1
A11: UAT Cycle 1 | B11: 2 | C11: 2 - Critical | D11: 1099 | E11: PBPTINTK-3366 - OSFI MVP 8.2 - 1E | F11: PBPTINTK-3366 - OSFI MVP 8.2 - 1E | G11: 45858 | H11: 1 | I11: 0 | J11: 0 | K11: 0 | L11: 0 | M11: 0 | N11: 0 | O11: 0 | P11: 4 | Q11: 5
A12: UAT Cycle 1 | B12: 3 | C12: 3 - Non-critical | D12: 1099 | E12: PBPTINTK-3366 - OSFI MVP 8.2 - 1E | F12: PBPTINTK-3366 - OSFI MVP 8.2 - 1E | G12: 45858 | H12: 0 | I12: 0 | J12: 0 | K12: 0 | L12: 0 | M12: 0 | N12: 0 | O12: 0 | P12: 9 | Q12: 9
A13: UAT Cycle 1 | B13: 4 | C13: 4 - Live with | D13: 1099 | E13: PBPTINTK-3366 - OSFI MVP 8.2 - 1E | F13: PBPTINTK-3366 - OSFI MVP 8.2 - 1E | G13: 45858 | H13: 0 | I13: 0 | J13: 0 | K13: 0 | L13: 0 | M13: 0 | N13: 0 | O13: 0 | P13: 0 | Q13: 0
... A17: UAT Cycle 2 | B17: 4 | C17: 4 - Live with | D17: 1099 | E17: PBPTINTK-3366 - OSFI MVP 8.2 - 1E | F17: PBPTINTK-3366 - OSFI MVP 8.2 - 1E | G17: 45858 | H17: 0 | I17: 0 | J17: 0 | K17: 0 | L17: 0 | M17: 0 | N17: 0 | O17: 0 | P17: 0 | Q17: 0

Sheet Sev 1 Aging
A1: BG_BUG_ID | B1: BG_STATUS | C1: BG_DETECTION_DATE | D1: BG_CLOSING_DATE | E1: NETWORKDAYS
A2: 3646 | B2: Closed | C2: 45756 | D2: 45772 | E2: 0 | F2: SIT Cycle 1
A3: 3666 | B3: Closed | C3: 45757 | D3: 45772 | E3: 0 | F3: SIT Cycle 1
A4: 3674 | B4: Closed | C4: 45757 | D4: 45763 | E4: 0 | F4: SIT Cycle 1
A5: 3748 | B5: Closed | C5: 45763 | D5: 45764 | E5: 0 | F5: SIT Cycle 1
A6: 3827 | B6: Closed | C6: 45769 | D6: 45769 | E6: 0 | F6: SIT Cycle 1
A7: 3828 | B7: Closed | C7: 45769 | D7: 45771 | E7: 0 | F7: SIT Cycle 1
A8: 3967 | B8: Closed | C8: 45777 | D8: 45777 | E8: 0 | F8: SIT Cycle 1
A9: 4077 | B9: Closed | C9: 45783 | D9: 45783 | E9: 0 | F9: SIT Cycle 2
A10: 4266 | B10: Closed | C10: 45791 | D10: 45792 | E10: 0 | F10: SIT Cycle 2
A11: 4420 | B11: Closed | C11: 45799 | D11: 45799 | E11: 0 | F11: SIT Cycle 2
A12: 4453 | B12: Closed | C12: 45798 | D12: 45799 | E12: 0 | F12: SIT Cycle 2
A13: 4850 | B13: Closed | C13: 45819 | D13: 45819 | E13: 0 | F13: UAT Cycle 1
A14: 5538 | B14: Closed | C14: 45846 | D14: 45846 | E14: 0 | F14: UAT Cycle 2

Sheet CumVar by RootCause & Severity
A1: CYCLE | B1: Root Cause Subtype/Status | C1: REL_ID | D1: REL_NAME | E1: PROJECT | F1: REL_END_DATE | G1: Sev 1 | H1: Sev 2 | I1: Sev 3 | J1: Sev 4
A2: SIT Cycle 1 | B2: Business Requirements | C2: 1099 | D2: PBPTINTK-3366 - OSFI MVP 8.2 - 1E | E2: PBPTINTK-3366 - OSFI MVP 8.2 - 1E | F2: 45858 | G2: 0 | H2: 0 | I2: 0 | J2: 0
A3: SIT Cycle 1 | B3: Code | C3: 1099 | D3: PBPTINTK-3366 - OSFI MVP 8.2 - 1E | E3: PBPTINTK-3366 - OSFI MVP 8.2 - 1E | F3: 45858 | G3: 6 | H3: 26 | I3: 12 | J3: 0
A4: SIT Cycle 1 | B4: Data | C4: 1099 | D4: PBPTINTK-3366 - OSFI MVP 8.2 - 1E | E4: PBPTINTK-3366 - OSFI MVP 8.2 - 1E | F4: 45858 | G4: 0 | H4: 1 | I4: 0 | J4: 0
A5: SIT Cycle 1 | B5: Design | C5: 1099 | D5: PBPTINTK-3366 - OSFI MVP 8.2 - 1E | E5: PBPTINTK-3366 - OSFI MVP 8.2 - 1E | F5: 45858 | G5: 0 | H5: 0 | I5: 0 | J5: 0
A6: SIT Cycle 1 | B6: Development Documentation | C6: 1099 | D6: PBPTINTK-3366 - OSFI MVP 8.2 - 1E | E6: PBPTINTK-3366 - OSFI MVP 8.2 - 1E | F6: 45858 | G6: 0 | H6: 0 | I6: 0 | J6: 0
A7: SIT Cycle 1 | B7: Duplicate | C7: 1099 | D7: PBPTINTK-3366 - OSFI MVP 8.2 - 1E | E7: PBPTINTK-3366 - OSFI MVP 8.2 - 1E | F7: 45858 | G7: 0 | H7: 0 | I7: 0 | J7: 0
A8: SIT Cycle 1 | B8: Existing Production Defect | C8: 1099 | D8: PBPTINTK-3366 - OSFI MVP 8.2 - 1E | E8: PBPTINTK-3366 - OSFI MVP 8.2 - 1E | F8: 45858 | G8: 0 | H8: 0 | I8: 0 | J8: 0
A9: SIT Cycle 1 | B9: Total | C9: 1099 | D9: PBPTINTK-3366 - OSFI MVP 8.2 - 1E | E9: PBPTINTK-3366 - OSFI MVP 8.2 - 1E | F9: 45858 | G9: 6 | H9: 26 | I9: 12 | J9: 0
A10: SIT Cycle 1 | B10: Total | C10: 1099 | D10: PBPTINTK-3366 - OSFI MVP 8.2 - 1E | E10: PBPTINTK-3366 - OSFI MVP 8.2 - 1E | F10: 45858 | G10: 6 | H10: 26 | I10: 5 | J10: 0
A11: SIT Cycle 1 | B11: Total | C11: 1099 | D11: PBPTINTK-3366 - OSFI MVP 8.2 - 1E | E11: PBPTINTK-3366 - OSFI MVP 8.2 - 1E | F11: 45858 | G11: 6 | H11: 26 | I11: 2 | J11: 0
A12: SIT Cycle 1 | B12: Total | C12: 1099 | D12: PBPTINTK-3366 - OSFI MVP 8.2 - 1E | E12: PBPTINTK-3366 - OSFI MVP 8.2 - 1E | F12: 45858 | G12: 6 | H12: 1 | I12: 12 | J12: 0
A13: SIT Cycle 1 | B13: Total | C13: 1099 | D13: PBPTINTK-3366 - OSFI MVP 8.2 - 1E | E13: PBPTINTK-3366 - OSFI MVP 8.2 - 1E | F13: 45858 | G13: 6 | H13: 1 | I13: 5 | J13: 0
... A165: UAT Cycle 2 | B165: Observation | C165: 1099 | D165: PBPTINTK-3366 - OSFI MVP 8.2 - 1E | E165: PBPTINTK-3366 - OSFI MVP 8.2 - 1E | F165: 45858 | G165: 0 | H165: 1 | I165: 0 | J165: 0

Sheet Cumulative SIT Effectiveness
B1: SIT/Feature | C1: UAT/Release | D1: SIT Effectiveness
A2: Total Number of Variances | B2: 102 | C2: 23 | D2: 0.816

Sheet CumVar by Department
A1: REL_ID | B1: CYCLE | C1: Assigned Person | D1: Sev | E1: Count
A2: 1099 | B2: SIT Cycle 1 | C2: nairvis | D2: 2 | E2: Closed | G2: 45755
A3: 1099 | B3: SIT Cycle 1 | C3: upadhdhr | D3: 1 | E3: Closed | G3: 45756
A4: 1099 | B4: SIT Cycle 1 | C4: ghutukad | D4: 2 | E4: Closed | G4: 45756
A5: 1099 | B5: SIT Cycle 1 | C5: ghutukad | D5: 2 | E5: Closed | G5: 45756
A6: 1099 | B6: SIT Cycle 1 | C6: upadhdhr | D6: 2 | E6: Closed | G6: 45756
A7: 1099 | B7: SIT Cycle 1 | C7: sharan | D7: 2 | E7: Closed | G7: 45756
A8: 1099 | B8: SIT Cycle 1 | C8: edla | D8: 2 | E8: Closed | G8: 45756
A9: 1099 | B9: SIT Cycle 1 | C9: ghutukad | D9: 2 | E9: Closed | G9: 45756
A10: 1099 | B10: SIT Cycle 1 | C10: edla | D10: 2 | E10: Closed | G10: 45756
A11: 1099 | B11: SIT Cycle 1 | C11: upadhdhr | D11: 2 | E11: Closed | G11: 45756
A12: 1099 | B12: SIT Cycle 1 | C12: upadhdhr | D12: 2 | E12: Closed | G12: 45756
A13: 1099 | B13: SIT Cycle 1 | C13: ghutukad | D13: 2 | E13: Closed | G13: 45757
... A126: 1099 | B126: UAT Cycle 1 | C126: sahoopri | D126: 2 | E126: New | G126: 45856

Sheet Ranges
A1: Look up value | B1: Row Number
A2: PROJECT NAME: | B2: =MATCH(A2,DSR!A:A,0) -> 3
A3: Cycle / Sprint: | B3: =MATCH(A3,DSR!A:A,0) -> 5
A4: OVERALL STATUS: | B4: =MATCH(A4,DSR!A:A,0) -> 7
A5: Date | B5: =MATCH(A5,DSR!A:A,0) -> 6
A6: App Stream | B6: =MATCH(A6,DSR!A:A,0) -> 8
A7: SUMMARY | B7: =MATCH(A7,DSR!A:A,0) -> 10
A8: TARGET SCHEDULE | B8: =MATCH(A8,DSR!A:A,0) -> 24
A9: Cycle / Sprint | B9: =MATCH(A9,DSR!A:A,0) -> 25
A10: Imp. Date: | B10: =MATCH(A10,DSR!A:A,0) -> 44
A11: TEST COVERAGE | B11: =MATCH(A11,DSR!A:A,0) -> 46
A12: Daily Target = | B12: =MATCH(A12,DSR!A:A,0) -> 47
A13: Total Planned | B13: =MATCH(A13,DSR!A:A,0) -> 60
... A20: CUMULATIVE SIT EFFECTIVENESS* | B20: =MATCH(A20,DSR!A:A,0) -> 170
A21: PROJECT NAME: Target Address | B21: ="C" & INDEX(A:B, MATCH("PROJECT NAME: ",A:A,0), 2) -> C3
A22: TARGET SCHEDULE - Number of Rows | B22: =COUNT(INDIRECT("DSR!B"&B9+1&":B"&(B10-1))) -> 4
A23: Cycle / Sprint: Target Address | B23: ="C" & INDEX(A:B, MATCH("Cycle / Sprint:",A:A,0), 2) -> C5
A24: OVERALL STATUS: Target Address | B24: ="C" & INDEX(A:B, MATCH("OVERALL STATUS: ",A:A,0), 2) -> C7
A25: Date Target Address | B25: ="C" & INDEX(A:B, MATCH("Date",A:A,0), 2) -> C6
A26: App Stream Target Address | B26: ="C" & INDEX(A:B, MATCH("App Stream",A:A,0), 2) -> C8
A27: TARGET SCHEDULE - Number of Rows | B27: {=SUM(IF(ISBLANK(INDIRECT("DSR!A"&(B9+1)&":A"&(B10-1))), 0, 1))} -> 4
A28: TARGET SCHEDULE - Number of Cycles | B28: =udfRowCount("Target Schedule", TRUE) -> 4
A29: TARGET SCHEDULE - Delete/Insert Rows | B29: =IF(B27>B28,"Delete",IF(B27<B28,"Insert","Do Nothing")) -> Do Nothing
A30: TARGET SCHEDULE - Number of Rows to be affected | B30: =ABS(B27-B28) -> 0
A31: TARGET SCHEDULE - Affected Rows | B31: =B8+2 &":"&B8+1+B30 -> 26:25
A32: Imp. Date: Target Address | B32: ="C" & INDEX(A:B, MATCH("Imp. Date:",A:A,0), 2) -> C44
C89: 0 | D89: 0 | E89: 0 | F89: 0
C90: 0 | D90: 0 | E90: 0 | F90: 0
C91: 0 | D91: 0 | E91: 0 | F91: 0
C92: 0 | D92: 0 | E92: 0 | F92: 0
C93: 0 | D93: 0 | E93: 0 | F93: 0
C94: 0 | D94: 0 | E94: 0 | F94: 0
C95: 0 | D95: 0 | E95: 0 | F95: 0
C96: 0 | D96: 0 | E96: 0 | F96: 0
C97: 0 | D97: 0 | E97: 0 | F97: 0
C98: 0 | D98: 0 | E98: 0 | F98: 0
C99: 0 | D99: 0 | E99: 0 | F99: 0
C100: 0 | D100: 0 | E100: 0 | F100: 0
... C107: 0 | D107: 0 | E107: 0 | F107: 0

Sheet Defect Open
A1: DAYS | B1: DEFECT_COUNT
A2: 0 | B2: 0
A3: 1 to 2 | B3: 0
A4: 3 to 5 | B4: 0
A5: 6 to 10 | B5: 0
A6: more than 10 | B6: 2

Sheet DSR
A1: DAILY STATUS REPORT
A3: PROJECT NAME: | C3: =Login!K5 -> PBPTINTK-3366 - OSFI MVP 8.2 - 1E
A5: Cycle / Sprint: | C5: SIT Cycle 2
A6: Date | C6: =TODAY() -> 45943 | EY6: Status | EZ6: Passed
A7: OVERALL STATUS: | C7: Yellow Trending Green | EY7: CYCLE | EZ7: SIT Cycle 2
A8: App Stream
EY9: Row Labels | EZ9: Sum of PENDING_TC | FA9: Sum of PLANNED_TC | FQ9: Row Labels | FR9: Sum of Total Open Defect | FS9: Sum of Closed Defect | FT9: Sum of New Defect | HK9: Row Labels | HL9: Sum of Closed Defects | HM9: Sum of Newly Opened Today | HN9: Sum of Total Open Defect
A10: SUMMARY | EY10: 5-May | EZ10: 500 | FA10: 510 | FQ10: 8-Apr | FR10: 0 | FS10: 1 | FT10: 1 | GE10: Row Labels | GF10: Sum of DEFECT_COUNT | HK10: CLASS | HL10: 0 | HM10: 0 | HN10: 1
A11: #N/A | EY11: 6-May | EZ11: 504 | FA11: 507 | FQ11: 9-Apr | FR11: 0 | FS11: 10 | FT11: 10 | GE11: 0 | GF11: 0 | HK11: CRM | HL11: 1 | HM11: 0 | HN11: 0
EY12: 7-May | EZ12: 451 | FA12: 479 | FQ12: 10-Apr | FR12: 0 | FS12: 5 | FT12: 5 | GE12: 1 to 2 | GF12: 0 | HK12: DDGS | HL12: 11 | HM12: 0 | HN12: 0
EY13: 8-May | EZ13: 403 | FA13: 441 | FQ13: 11-Apr | FR13: 0 | FS13: 4 | FT13: 4 | GE13: 3 to 5 | GF13: 0 | HK13: Decision Manager | HL13: 2 | HM13: 0 | HN13: 0
EY14: 9-May | EZ14: 363 | FA14: 402 | FQ14: 14-Apr | FR14: 0 | FS14: 3 | FT14: 3 | GE14: 6 to 10 | GF14: 0 | HK14: ECM | HL14: 1 | HM14: 0 | HN14: 0
EY15: 12-May | EZ15: 314 | FA15: 358 | FQ15: 16-Apr | FR15: 0 | FS15: 5 | FT15: 5 | GE15: more than 10 | GF15: 2 | HK15: Envoy | HL15: 1 | HM15: 0 | HN15: 1
EY16: 13-May | EZ16: 304 | FA16: 331 | FQ16: 17-Apr | FR16: 0 | FS16: 1 | FT16: 1 | GE16: Grand Total | GF16: 2 | HK16: LCMS | HL16: 12 | HM16: 0 | HN16: 0
A17: Variance Notes | EY17: 14-May | EZ17: 279 | FA17: 305 | FQ17: 18-Apr | FR17: 0 | FS17: 1 | FT17: 1 | HK17: mMortgage | HL17: 95 | HM17: 0 | HN17: 0
A18: Issue Details | C18: Resolution Owner | E18: Status/Progress | EY18: 15-May | EZ18: 277 | FA18: 291 | FQ18: 21-Apr | FR18: 0 | FS18: 1 | FT18: 1 | HK18: Grand Total | HL18: 123 | HM18: 0 | HN18: 2
A19: #VALUE! | EY19: 16-May | EZ19: 265 | FA19: 278 | FQ19: 22-Apr | FR19: 0 | FS19: 2 | FT19: 2
EY20: 19-May | EZ20: 264 | FA20: 271 | FQ20: 23-Apr | FR20: 0 | FS20: 3 | FT20: 3
EY21: 20-May | EZ21: 233 | FA21: 252 | FQ21: 24-Apr | FR21: 0 | FS21: 3 | FT21: 3
EY22: 21-May | EZ22: 196 | FA22: 224 | FQ22: 25-Apr | FR22: 0 | FS22: 6 | FT22: 6
EY23: 22-May | EZ23: 188 | FA23: 206 | FQ23: 28-Apr | FR23: 0 | FS23: 3 | FT23: 3
A24: TARGET SCHEDULE | EY24: 23-May | EZ24: 130 | FA24: 168 | FQ24: 29-Apr | FR24: 0 | FS24: 2 | FT24: 2
A25: {=_xlfn._xlws.FILTER(INDIRECT("'Target Schedule'!A:B"), INDIRECT("'Target Schedule'!A:A")<>0)} -> Cycle / Sprint | B25: Planned Start | C25: Actual Start | D25: {=_xlfn._xlws.FILTER(INDIRECT("'Target Schedule'!D:D"), INDIRECT("'Target Schedule'!A:A")<>0)} -> Planned End | E25: Actual End | EY25: 26-May | EZ25: 60 | FA25: 114 | FQ25: 30-Apr | FR25: 0 | FS25: 2 | FT25: 2
A26: SIT Cycle 1 | B26: 45754 | C26: 45754 | D26: 45779 | E26: 45779 | EY26: 27-May | EZ26: 58 | FA26: 86 | FQ26: 2-May | FR26: 0 | FS26: 1 | FT26: 1
A27: SIT Cycle 2 | B27: 45782 | C27: 45782 | D27: 45812 | E27: 45812 | EY27: 28-May | EZ27: 16 | FA27: 51 | FQ27: 5-May | FR27: 0 | FS27: 2 | FT27: 2
A28: UAT Cycle 1 | B28: 45813 | C28: 45813 | D28: 45833 | E28: 45833 | EY28: 29-May | EZ28: 31 | FA28: 41 | FQ28: 6-May | FR28: 0 | FS28: 4 | FT28: 4
A29: UAT Cycle 2 | B29: 45834 | C29: 45834 | D29: 45847 | E29: 45847 | EY29: 30-May | EZ29: 5 | FA29: 23 | FQ29: 7-May | FR29: 0 | FS29: 2 | FT29: 2
EY30: 2-Jun | EZ30: 11 | FA30: 17 | FQ30: 8-May | FR30: 0 | FS30: 2 | FT30: 2
EY31: 3-Jun | EZ31: -15 | FA31: 1 | FQ31: 12-May | FR31: 0 | FS31: 1 | FT31: 1
FQ32: 13-May | FR32: 0 | FS32: 5 | FT32: 5
FQ33: 14-May | FR33: 0 | FS33: 2 | FT33: 2
FQ34: 15-May | FR34: 0 | FS34: 3 | FT34: 3
FQ35: 16-May | FR35: 0 | FS35: 1 | FT35: 1
FQ36: 19-May | FR36: 0 | FS36: 1 | FT36: 1
FQ37: 20-May | FR37: 0 | FS37: 4 | FT37: 4
FQ38: 21-May | FR38: 0 | FS38: 3 | FT38: 3
FQ39: 22-May | FR39: 0 | FS39: 4 | FT39: 4
FQ40: 23-May | FR40: 0 | FS40: 2 | FT40: 2
FQ41: 26-May | FR41: 0 | FS41: 1 | FT41: 1
FQ42: 27-May | FR42: 0 | FS42: 3 | FT42: 3
...

Sheet Application Defect
A1: Application | B1: Closed Defects | C1: Newly Opened Today | D1: Total Open Defect | E1: Total Defect
A2: CLASS | B2: 0 | C2: 0 | D2: 1 | E2: 1
A3: CRM | B3: 1 | C3: 0 | D3: 0 | E3: 1
A4: DDGS | B4: 11 | C4: 0 | D4: 0 | E4: 11
A5: Decision Manager | B5: 2 | C5: 0 | D5: 0 | E5: 2
A6: ECM | B6: 1 | C6: 0 | D6: 0 | E6: 1
A7: Envoy | B7: 1 | C7: 0 | D7: 1 | E7: 2
A8: LCMS | B8: 12 | C8: 0 | D8: 0 | E8: 12
A9: mMortgage | B9: 95 | C9: 0 | D9: 0 | E9: 95
A10: TOTAL From All teams | B10: 123 | C10: 0 | D10: 2 | E10: 125

Sheet GeneratedTextSummaries
A2: Summary | B2: =DSR!C62+DSR!D62&" out of "&DSR!C60+DSR!D60&" ("&ROUND(100*DSR!F62,1)&"%) tests have been executed with a pass rate of "&ROUND(100*DSR!F63,1)&"%. "&DSR!C61+DSR!D61&" tests have been planned to be done by today ("&IFERROR(ROUND(100*(DSR!C62+DSR!D62)/(DSR!C61+DSR!D61),1),0)&"% reached). "&DSR!F128&" defects have been logged. "&DSR!F120+DSR!F119+DSR!F124&" defects are open, "&DSR!F122+DSR!F123&" are being monitored and "&DSR!F127+DSR!F121+DSR!F125+DSR!F126&" defects are closed. Today, "&DSR!C49+DSR!D49&" out of the "&DSR!C47&" daily target tests have been executed with a pass rate of "&ROUND(100*DSR!E50,1)&"%. "&DSR!C112&" defects were opened and "&DSR!C113&" defects were closed." -> #N/A
A4: Variances | B4: {=_xlfn.TEXTJOIN("", TRUE,_xlfn.ANCHORARRAY( D6) & " Sev " &_xlfn.ANCHORARRAY( B6) & " defect, assigned to " &_xlfn.ANCHORARRAY( E6) & ": " &_xlfn.ANCHORARRAY( C6) & " ")} -> #VALUE!
B5: Severity | C5: Details | D5: Status | E5: Assigned
B6: {=(_xlfn._xlws.FILTER('CumVar by Department'!D:D,'CumVar by Department'!F:F<>0))} -> #VALUE! | C6: {=LEFT(_xlfn._xlws.FILTER('CumVar by Department'!F:F,'CumVar by Department'!F:F<>0), 1000)} -> #VALUE! | D6: {=_xlfn.LET(_xlpm.status,_xlfn._xlws.FILTER('CumVar by Department'!E:E,'CumVar by Department'!F:F<>0),IF(_xlpm.status="New",_xlpm.status,_xlpm.status&"ed"))} -> #VALUE! | E6: {=_xlfn.LET(_xlpm.names, _xlfn._xlws.FILTER('CumVar by Department'!C:C, 'CumVar by Department'!F:F<>0), PROPER(LEFT(_xlpm.names))& " " &PROPER(MID(_xlpm.names, 2, 100)))} -> #VALUE!

Sheet Daily Target
A1: Cycle | B1: {=INDIRECT("DSR!C"&Ranges!B3)} -> SIT Cycle 2 | D1: Planned Manual for Cycle | E1: =DSR!C60 -> 142
A2: Cycle Start | B2: =VLOOKUP(B1, DSR!A26:E43, 3) -> 45782 | D2: Planned Automated for Cycle | E2: =DSR!D60 -> 378
A3: Cycle End | B3: =VLOOKUP(B1, DSR!A26:E43, 5) -> 45812
A4: Number of Workdays | B4: =NETWORKDAYS(B2,B3) -> 23
B5: If the formulas in this sheet are broken, that is because the actual start and end date fields in the DSR are empty
B6: Feel free to delete the formulas in this sheet and replace them with the actual targets
B7: Note, if you delete the formulas, once the next cycle starts the values in the this sheet will be wrong
A8: Date | B8: Manual Daily Target | C8: Automated Target Daily Target | D8: Manual Cumulative Target | E8: Automated Cumulative Target
A9: {=_xlfn.MAP(_xlfn.SEQUENCE(B4,1,0), _xlfn.LAMBDA(_xlpm.x, WORKDAY(B2, _xlpm.x)))} -> #NAME? | B9: {=_xlfn.SEQUENCE(B4,1,QUOTIENT(E1,B4),0)+IF(_xlfn.SEQUENCE(B4,1)<=MOD(E1,B4), TRUE)} -> 7 | C9: {=_xlfn.SEQUENCE(B4,1,QUOTIENT(E2,B4),0)+IF(_xlfn.SEQUENCE(B4,1)<=MOD(E2,B4), TRUE)} -> 17 | D9: =SUM(B$9:B9) -> 7 | E9: =SUM(C$9:C9) -> 17
B10: 7 | C10: 17 | D10: =SUM(B$9:B10) -> 14 | E10: =SUM(C$9:C10) -> 34
B11: 7 | C11: 17 | D11: =SUM(B$9:B11) -> 21 | E11: =SUM(C$9:C11) -> 51
B12: 7 | C12: 17 | D12: =SUM(B$9:B12) -> 28 | E12: =SUM(C$9:C12) -> 68
B13: 6 | C13: 17 | D13: =SUM(B$9:B13) -> 34 | E13: =SUM(C$9:C13) -> 85
B14: 6 | C14: 17 | D14: =SUM(B$9:B14) -> 40 | E14: =SUM(C$9:C14) -> 102
B15: 6 | C15: 17 | D15: =SUM(B$9:B15) -> 46 | E15: =SUM(C$9:C15) -> 119
B16: 6 | C16: 17 | D16: =SUM(B$9:B16) -> 52 | E16: =SUM(C$9:C16) -> 136
B17: 6 | C17: 17 | D17: =SUM(B$9:B17) -> 58 | E17: =SUM(C$9:C17) -> 153
B18: 6 | C18: 17 | D18: =SUM(B$9:B18) -> 64 | E18: =SUM(C$9:C18) -> 170
B19: 6 | C19: 16 | D19: =SUM(B$9:B19) -> 70 | E19: =SUM(C$9:C19) -> 186
B20: 6 | C20: 16 | D20: =SUM(B$9:B20) -> 76 | E20: =SUM(C$9:C20) -> 202
B21: 6 | C21: 16 | D21: =SUM(B$9:B21) -> 82 | E21: =SUM(C$9:C21) -> 218
... B31: 6 | C31: 16 | D31: =SUM(B$9:B31) -> 142 | E31: =SUM(C$9:C31) -> 378

Sheet Trend Test Coverage
A1: CYCLE | B1: Status | C1: EXECUTION_DATE | D1: PENDING_TC | E1: PLANNED_TC
A2: SIT Cycle 1 | B2: Passed | C2: 45757 | D2: 396 | E2: 406
A3: SIT Cycle 1 | B3: Passed | C3: 45761 | D3: 372 | E3: 389
A4: SIT Cycle 1 | B4: Passed | C4: 45762 | D4: 365 | E4: 377
A5: SIT Cycle 1 | B5: Passed | C5: 45764 | D5: 367 | E5: 372
A6: SIT Cycle 1 | B6: Passed | C6: 45765 | D6: 358 | E6: 365
A7: SIT Cycle 1 | B7: Passed | C7: 45769 | D7: 341 | E7: 353
A8: SIT Cycle 1 | B8: Passed | C8: 45770 | D8: 351 | E8: 352
A9: SIT Cycle 1 | B9: Passed | C9: 45772 | D9: 350 | E9: 351
A10: SIT Cycle 1 | B10: Passed | C10: 45775 | D10: 319 | E10: 335
A11: SIT Cycle 1 | B11: Passed | C11: 45776 | D11: 289 | E11: 312
A12: SIT Cycle 1 | B12: Passed | C12: 45777 | D12: 280 | E12: 296
A13: SIT Cycle 1 | B13: Passed | C13: 45779 | D13: 246 | E13: 271
... A62: UAT Cycle 2 | B62: Passed | C62: 45847 | D62: -18 | E62: 0

Sheet AssignPeopleToDepartments
A1: Assigned Person | B1: Department | F1: Avaliable Departments
A2: Henry | B2: QC | F2: ADM
A3: nairvis | B3: ADM | F3: Business
A4: upadhdhr | B4: QC | F4: B&SA
A5: ghutukad | B5: TEM | F5: QC
A6: sharan | B6: QC | F6: TEM
A7: edla | B7: B&SA
A8: nairt | B8: ADM
A9: sonavans | B9: QC
A10: asingh3 | B10: ADM
A11: katre | B11: QC
A12: royman | B12: QC
A13: mandald | B13: B&SA
A14: sinarshd | B14: Business
A15: punmiaa | B15: QC
A16: parekhs | B16: ADM
A17: chintalh | B17: ADM
A18: lellis | B18: ADM
... A21: kchugh | B21: ADM
A22: dmallick
A23: sahoopri
A24: tiwarir
A25: patilgau
A26: jaspalsi
A27: lokesha
A28: sinhanis
A29: bodara
A30: chede
A31: waghe
A32: raide
A33: rpothal
... A149: kumaradh

Sheet Trend Defect Coverage
A1: DATE | B1: Total Open Defect | C1: New Defect | D1: Closed Defect
A2: 45755 | B2: 0 | C2: 1 | D2: 1
A3: 45756 | B3: 0 | C3: 10 | D3: 10
A4: 45757 | B4: 0 | C4: 5 | D4: 5
A5: 45758 | B5: 0 | C5: 4 | D5: 4
A6: 45761 | B6: 0 | C6: 3 | D6: 3
A7: 45763 | B7: 0 | C7: 5 | D7: 5
A8: 45764 | B8: 0 | C8: 1 | D8: 1
A9: 45765 | B9: 0 | C9: 1 | D9: 1
A10: 45768 | B10: 0 | C10: 1 | D10: 1
A11: 45769 | B11: 0 | C11: 2 | D11: 2
A12: 45770 | B12: 0 | C12: 3 | D12: 3
A13: 45771 | B13: 0 | C13: 3 | D13: 3
... A55: 45856 | B55: 1 | C55: 1 | D55: 0

Sheet AssignPeopleToDepartmentsHelper
A1: Assigned Person | B1: {=_xlfn._xlws.FILTER(AssignPeopleToDepartments!B:B, AssignPeopleToDepartments!B:B<>0)} -> Department | C1: Sev 1 | D1: Sev 2 | E1: Sev 3 | F1: Sev 4
A2: {=IFERROR(IFERROR(_xlfn.VSTACK(INDIRECT("AssignPeopleToDepartments!A2:A"&MAX(2,(AssignPeopleToDepartments!A:A<>"")*(ROW(A:A)))),_xlfn._xlws.FILTER(_xlfn.UNIQUE('CumVar by Department'!C2:C1000),IF(ISNA(_xlfn.XMATCH(_xlfn.UNIQUE('CumVar by Department'!C2:C1000),INDIRECT("AssignPeopleToDepartments!A2:A"&MAX(2,(AssignPeopleToDepartments!A:A<>"")*(ROW(A:A)))))),_xlfn.UNIQUE('CumVar by Department'!C2:C1000),0)<>0)),_xlfn._xlws.FILTER(_xlfn.UNIQUE(AssignPeopleToDepartments!A2:A1000),_xlfn.UNIQUE(AssignPeopleToDepartments!A2:A1000)<>0)),0)} -> Henry | B2: QC | C2: {=COUNTIFS('CumVar by Department'!$C:$C,_xlfn.ANCHORARRAY( $A$2), 'CumVar by Department'!$D:$D, 1)} -> 0 | D2: {=COUNTIFS('CumVar by Department'!$C:$C,_xlfn.ANCHORARRAY( $A$2), 'CumVar by Department'!$D:$D, 2)} -> 0 | E2: {=COUNTIFS('CumVar by Department'!$C:$C,_xlfn.ANCHORARRAY( $A$2), 'CumVar by Department'!$D:$D, 3)} -> 0 | F2: {=COUNTIFS('CumVar by Department'!$C:$C,_xlfn.ANCHORARRAY( $A$2), 'CumVar by Department'!$D:$D, 4)} -> 0
A3: nairvis | B3: ADM | C3: 0 | D3: 2 | E3: 0 | F3: 0
A4: upadhdhr | B4: QC | C4: 7 | D4: 28 | E4: 36 | F4: 0
A5: ghutukad | B5: TEM | C5: 0 | D5: 6 | E5: 8 | F5: 0
A6: sharan | B6: QC | C6: 0 | D6: 1 | E6: 0 | F6: 0
A7: edla | B7: B&SA | C7: 1 | D7: 5 | E7: 0 | F7: 0
A8: nairt | B8: ADM | C8: 0 | D8: 2 | E8: 0 | F8: 0
A9: sonavans | B9: QC | C9: 1 | D9: 6 | E9: 0 | F9: 0
A10: asingh3 | B10: ADM | C10: 1 | D10: 0 | E10: 0 | F10: 0
A11: katre | B11: QC | C11: 0 | D11: 0 | E11: 2 | F11: 0
A12: royman | B12: QC | C12: 0 | D12: 1 | E12: 4 | F12: 0
A13: mandald | B13: B&SA | C13: 0 | D13: 2 | E13: 0 | F13: 0
A14: sinarshd | B14: Business | C14: 1 | D14: 1 | E14: 0 | F14: 0
... A21: kchugh | B21: ADM | C21: 0 | D21: 1 | E21: 0 | F21: 0
A22: dmallick | C22: 1 | D22: 0 | E22: 0 | F22: 0
A23: sahoopri | C23: 0 | D23: 1 | E23: 0 | F23: 0
A24: tiwarir | C24: 0 | D24: 0 | E24: 0 | F24: 0
A25: patilgau | C25: 0 | D25: 0 | E25: 0 | F25: 0
A26: jaspalsi | C26: 0 | D26: 0 | E26: 0 | F26: 0
A27: lokesha | C27: 0 | D27: 0 | E27: 0 | F27: 0
A28: sinhanis | C28: 0 | D28: 0 | E28: 0 | F28: 0
A29: bodara | C29: 0 | D29: 0 | E29: 0 | F29: 0
A30: chede | C30: 0 | D30: 0 | E30: 0 | F30: 0
A31: waghe | C31: 0 | D31: 0 | E31: 0 | F31: 0
A32: raide | C32: 0 | D32: 0 | E32: 0 | F32: 0
A33: rpothal | C33: 0 | D33: 0 | E33: 0 | F33: 0
... A149: kumaradh | C149: 0 | D149: 0 | E149: 0 | F149: 0

Sheet AfterRunAddresses
A1: Lookup Value | B1: Row Number
A2: App Stream | B2: ="C" & MATCH(A2,DSR!A:A,0) -> C8
A3: Summary | B3: ="A" & MATCH(A3,DSR!A:A,0)+1 -> A11
A4: Daily Target = | B4: ="C" & MATCH(A4,DSR!A:A,0) -> C47
A5: Issue Details | B5: ="A" & MATCH(A5,DSR!A:A,0)+1 -> A19
A6: Resolution Owner | B6: ="C" & MATCH(A6,DSR!C:C,0)+1 -> C19
A7: Status/Progress | B7: ="E" & MATCH(A7,DSR!E:E,0)+1 -> E19

Sheet Favourite TestSet Folders
A1: /Root/BTM Pay No Pay Release-1/BTM Pay No Pay Release-1A: Migration
A2: /Root/BTM Pay No Pay Release-1/BTM Pay No Pay Release-1A: Migration/Baseline/FSR
A3: /Root/BTM Pay No Pay Release-1/BTM Pay No Pay Release-1A: Migration/Baseline/FSR/3. iTracII/1 ABM Deposit Monitoring
A4: /Root/BTM Pay No Pay Release-1/BTM Pay No Pay Release-1A: Migration/Baseline/FSR/FRM - FICO/1 Communication Channels
A5: /Root/BTM Pay No Pay Release-1/BTM Pay No Pay Release-1A: Migration/Baseline/FSR/FRM - FICO/4 Mass Compromise/FRM
A6: /Root/BTM Pay No Pay Release-1/BTM Pay No Pay Release-1A: Migration/Baseline/FSR/PRM/PRM GUI
A7: /Root/BTM Pay No Pay Release-1/BTM Pay No Pay Release-1A: Migration/Baseline/FSR/PRM/PRM NRT to PRM GUI/TSYS to PRM GUI

Sheet Columns
A1: LOB | B1: DOMAIN_NAME | C1: PROJECT_NAME | D1: DB_NAME | E1: SF_TABLE_NAME | F1: SF_USER_LABEL | G1: SF_COLUMN_NAME
A2: PBPT | B2: MLIDT | C2: Lending_F25 | D2: mlidt_lending_f25_db | E2: BUG | F2: Defect ID | G2: BG_BUG_ID
A3: PBPT | B3: MLIDT | C3: Lending_F25 | D3: mlidt_lending_f25_db | E3: BUG | F3: Closed on Date | G3: BG_CLOSING_DATE
A4: PBPT | B4: MLIDT | C4: Lending_F25 | D4: mlidt_lending_f25_db | E4: BUG | F4: Detected By | G4: BG_DETECTED_BY
A5: PBPT | B5: MLIDT | C5: Lending_F25 | D5: mlidt_lending_f25_db | E5: BUG | F5: Detected on Date | G5: BG_DETECTION_DATE
A6: PBPT | B6: MLIDT | C6: Lending_F25 | D6: mlidt_lending_f25_db | E6: BUG | F6: Priority | G6: BG_PRIORITY
A7: PBPT | B7: MLIDT | C7: Lending_F25 | D7: mlidt_lending_f25_db | E7: BUG | F7: Severity | G7: BG_SEVERITY
A8: PBPT | B8: MLIDT | C8: Lending_F25 | D8: mlidt_lending_f25_db | E8: BUG | F8: Status | G8: BG_STATUS
A9: PBPT | B9: MLIDT | C9: Lending_F25 | D9: mlidt_lending_f25_db | E9: BUG | F9: Detected in Release | G9: BG_DETECTED_IN_REL
A10: PBPT | B10: MLIDT | C10: Lending_F25 | D10: mlidt_lending_f25_db | E10: BUG | F10: Detected in Cycle | G10: BG_DETECTED_IN_RCYC
A11: PBPT | B11: MLIDT | C11: Lending_F25 | D11: mlidt_lending_f25_db | E11: BUG | F11: Root Cause | G11: BG_USER_TEMPLATE_01
A12: PBPT | B12: MLIDT | C12: Lending_F25 | D12: mlidt_lending_f25_db | E12: BUG | F12: *Detected in Phase | G12: BG_USER_TEMPLATE_10
... A44: PBPT | B44: MLIDT | C44: Lending_F25 | D44: mlidt_lending_f25_db | E44: TESTCYCL | F44: Target Cycle | G44: TC_ASSIGN_RCYC
